[2024-04-21T21:05:47.177+0000] {taskinstance.py:1979} INFO - Dependencies all met for dep_context=non-requeueable deps ti=<TaskInstance: workshop2_dags.transformation_db manual__2024-04-21T21:02:30.540069+00:00 [queued]>
[2024-04-21T21:05:47.193+0000] {taskinstance.py:1979} INFO - Dependencies all met for dep_context=requeueable deps ti=<TaskInstance: workshop2_dags.transformation_db manual__2024-04-21T21:02:30.540069+00:00 [queued]>
[2024-04-21T21:05:47.194+0000] {taskinstance.py:2193} INFO - Starting attempt 1 of 2
[2024-04-21T21:05:47.220+0000] {taskinstance.py:2217} INFO - Executing <Task(PythonOperator): transformation_db> on 2024-04-21 21:02:30.540069+00:00
[2024-04-21T21:05:47.231+0000] {standard_task_runner.py:60} INFO - Started process 105 to run task
[2024-04-21T21:05:47.235+0000] {standard_task_runner.py:87} INFO - Running: ['***', 'tasks', 'run', 'workshop2_dags', 'transformation_db', 'manual__2024-04-21T21:02:30.540069+00:00', '--job-id', '62', '--raw', '--subdir', 'DAGS_FOLDER/Airflow/dags_etl.py', '--cfg-path', '/tmp/tmpq4mrkge8']
[2024-04-21T21:05:47.237+0000] {standard_task_runner.py:88} INFO - Job 62: Subtask transformation_db
[2024-04-21T21:05:47.434+0000] {task_command.py:423} INFO - Running <TaskInstance: workshop2_dags.transformation_db manual__2024-04-21T21:02:30.540069+00:00 [running]> on host 2a6cdc973ec3
[2024-04-21T21:05:47.799+0000] {taskinstance.py:2513} INFO - Exporting env vars: AIRFLOW_CTX_DAG_EMAIL='***@example.com' AIRFLOW_CTX_DAG_OWNER='***' AIRFLOW_CTX_DAG_ID='workshop2_dags' AIRFLOW_CTX_TASK_ID='transformation_db' AIRFLOW_CTX_EXECUTION_DATE='2024-04-21T21:02:30.540069+00:00' AIRFLOW_CTX_TRY_NUMBER='1' AIRFLOW_CTX_DAG_RUN_ID='manual__2024-04-21T21:02:30.540069+00:00'
[2024-04-21T21:05:47.803+0000] {taskinstance.py:2731} ERROR - Task failed with exception
Traceback (most recent call last):
  File "/home/airflow/.local/lib/python3.9/site-packages/airflow/models/taskinstance.py", line 444, in _execute_task
    result = _execute_callable(context=context, **execute_callable_kwargs)
  File "/home/airflow/.local/lib/python3.9/site-packages/airflow/models/taskinstance.py", line 414, in _execute_callable
    return execute_callable(context=context, **execute_callable_kwargs)
  File "/home/airflow/.local/lib/python3.9/site-packages/airflow/operators/python.py", line 200, in execute
    return_value = self.execute_callable()
  File "/home/airflow/.local/lib/python3.9/site-packages/airflow/operators/python.py", line 217, in execute_callable
    return self.python_callable(*self.op_args, **self.op_kwargs)
TypeError: transformation_db() missing 1 required positional argument: 'df_grammys'
[2024-04-21T21:05:47.851+0000] {taskinstance.py:1149} INFO - Marking task as UP_FOR_RETRY. dag_id=workshop2_dags, task_id=transformation_db, execution_date=20240421T210230, start_date=20240421T210547, end_date=20240421T210547
[2024-04-21T21:05:47.878+0000] {standard_task_runner.py:107} ERROR - Failed to execute job 62 for task transformation_db (transformation_db() missing 1 required positional argument: 'df_grammys'; 105)
[2024-04-21T21:05:47.930+0000] {local_task_job_runner.py:234} INFO - Task exited with return code 1
[2024-04-21T21:05:47.994+0000] {taskinstance.py:3312} INFO - 0 downstream tasks scheduled from follow-on schedule check
