[2024-04-21T20:45:48.944+0000] {taskinstance.py:1979} INFO - Dependencies all met for dep_context=non-requeueable deps ti=<TaskInstance: workshop2_dags.transformation_db manual__2024-04-21T20:33:56.093233+00:00 [queued]>
[2024-04-21T20:45:48.970+0000] {taskinstance.py:1979} INFO - Dependencies all met for dep_context=requeueable deps ti=<TaskInstance: workshop2_dags.transformation_db manual__2024-04-21T20:33:56.093233+00:00 [queued]>
[2024-04-21T20:45:48.971+0000] {taskinstance.py:2193} INFO - Starting attempt 1 of 2
[2024-04-21T20:45:49.010+0000] {taskinstance.py:2217} INFO - Executing <Task(PythonOperator): transformation_db> on 2024-04-21 20:33:56.093233+00:00
[2024-04-21T20:45:49.027+0000] {standard_task_runner.py:60} INFO - Started process 202 to run task
[2024-04-21T20:45:49.032+0000] {standard_task_runner.py:87} INFO - Running: ['***', 'tasks', 'run', 'workshop2_dags', 'transformation_db', 'manual__2024-04-21T20:33:56.093233+00:00', '--job-id', '52', '--raw', '--subdir', 'DAGS_FOLDER/Airflow/dags_etl.py', '--cfg-path', '/tmp/tmpyx7k515z']
[2024-04-21T20:45:49.034+0000] {standard_task_runner.py:88} INFO - Job 52: Subtask transformation_db
[2024-04-21T20:45:49.308+0000] {task_command.py:423} INFO - Running <TaskInstance: workshop2_dags.transformation_db manual__2024-04-21T20:33:56.093233+00:00 [running]> on host 6e4579bd97b2
[2024-04-21T20:45:50.432+0000] {taskinstance.py:2513} INFO - Exporting env vars: AIRFLOW_CTX_DAG_EMAIL='***@example.com' AIRFLOW_CTX_DAG_OWNER='***' AIRFLOW_CTX_DAG_ID='workshop2_dags' AIRFLOW_CTX_TASK_ID='transformation_db' AIRFLOW_CTX_EXECUTION_DATE='2024-04-21T20:33:56.093233+00:00' AIRFLOW_CTX_TRY_NUMBER='1' AIRFLOW_CTX_DAG_RUN_ID='manual__2024-04-21T20:33:56.093233+00:00'
[2024-04-21T20:45:50.437+0000] {taskinstance.py:2731} ERROR - Task failed with exception
Traceback (most recent call last):
  File "/home/airflow/.local/lib/python3.9/site-packages/airflow/models/taskinstance.py", line 444, in _execute_task
    result = _execute_callable(context=context, **execute_callable_kwargs)
  File "/home/airflow/.local/lib/python3.9/site-packages/airflow/models/taskinstance.py", line 414, in _execute_callable
    return execute_callable(context=context, **execute_callable_kwargs)
  File "/home/airflow/.local/lib/python3.9/site-packages/airflow/operators/python.py", line 200, in execute
    return_value = self.execute_callable()
  File "/home/airflow/.local/lib/python3.9/site-packages/airflow/operators/python.py", line 217, in execute_callable
    return self.python_callable(*self.op_args, **self.op_kwargs)
TypeError: transformation_db() missing 1 required positional argument: 'df_grammys'
[2024-04-21T20:45:50.498+0000] {taskinstance.py:1149} INFO - Marking task as UP_FOR_RETRY. dag_id=workshop2_dags, task_id=transformation_db, execution_date=20240421T203356, start_date=20240421T204548, end_date=20240421T204550
[2024-04-21T20:45:50.530+0000] {standard_task_runner.py:107} ERROR - Failed to execute job 52 for task transformation_db (transformation_db() missing 1 required positional argument: 'df_grammys'; 202)
[2024-04-21T20:45:50.572+0000] {local_task_job_runner.py:234} INFO - Task exited with return code 1
[2024-04-21T20:45:50.672+0000] {taskinstance.py:3312} INFO - 0 downstream tasks scheduled from follow-on schedule check
