[2024-04-21T20:46:53.896+0000] {taskinstance.py:1979} INFO - Dependencies all met for dep_context=non-requeueable deps ti=<TaskInstance: workshop2_dags.transformation_db manual__2024-04-21T20:33:56.093233+00:00 [queued]>
[2024-04-21T20:46:53.918+0000] {taskinstance.py:1979} INFO - Dependencies all met for dep_context=requeueable deps ti=<TaskInstance: workshop2_dags.transformation_db manual__2024-04-21T20:33:56.093233+00:00 [queued]>
[2024-04-21T20:46:53.919+0000] {taskinstance.py:2193} INFO - Starting attempt 2 of 2
[2024-04-21T20:46:53.949+0000] {taskinstance.py:2217} INFO - Executing <Task(PythonOperator): transformation_db> on 2024-04-21 20:33:56.093233+00:00
[2024-04-21T20:46:53.960+0000] {standard_task_runner.py:60} INFO - Started process 212 to run task
[2024-04-21T20:46:53.964+0000] {standard_task_runner.py:87} INFO - Running: ['***', 'tasks', 'run', 'workshop2_dags', 'transformation_db', 'manual__2024-04-21T20:33:56.093233+00:00', '--job-id', '53', '--raw', '--subdir', 'DAGS_FOLDER/Airflow/dags_etl.py', '--cfg-path', '/tmp/tmpsgzqjzfg']
[2024-04-21T20:46:53.966+0000] {standard_task_runner.py:88} INFO - Job 53: Subtask transformation_db
[2024-04-21T20:46:54.136+0000] {task_command.py:423} INFO - Running <TaskInstance: workshop2_dags.transformation_db manual__2024-04-21T20:33:56.093233+00:00 [running]> on host 6e4579bd97b2
[2024-04-21T20:46:54.363+0000] {taskinstance.py:2513} INFO - Exporting env vars: AIRFLOW_CTX_DAG_EMAIL='***@example.com' AIRFLOW_CTX_DAG_OWNER='***' AIRFLOW_CTX_DAG_ID='workshop2_dags' AIRFLOW_CTX_TASK_ID='transformation_db' AIRFLOW_CTX_EXECUTION_DATE='2024-04-21T20:33:56.093233+00:00' AIRFLOW_CTX_TRY_NUMBER='2' AIRFLOW_CTX_DAG_RUN_ID='manual__2024-04-21T20:33:56.093233+00:00'
[2024-04-21T20:46:54.366+0000] {taskinstance.py:2731} ERROR - Task failed with exception
Traceback (most recent call last):
  File "/home/airflow/.local/lib/python3.9/site-packages/airflow/models/taskinstance.py", line 444, in _execute_task
    result = _execute_callable(context=context, **execute_callable_kwargs)
  File "/home/airflow/.local/lib/python3.9/site-packages/airflow/models/taskinstance.py", line 414, in _execute_callable
    return execute_callable(context=context, **execute_callable_kwargs)
  File "/home/airflow/.local/lib/python3.9/site-packages/airflow/operators/python.py", line 200, in execute
    return_value = self.execute_callable()
  File "/home/airflow/.local/lib/python3.9/site-packages/airflow/operators/python.py", line 217, in execute_callable
    return self.python_callable(*self.op_args, **self.op_kwargs)
TypeError: transformation_db() missing 1 required positional argument: 'df_grammys'
[2024-04-21T20:46:54.413+0000] {taskinstance.py:1149} INFO - Marking task as FAILED. dag_id=workshop2_dags, task_id=transformation_db, execution_date=20240421T203356, start_date=20240421T204653, end_date=20240421T204654
[2024-04-21T20:46:54.438+0000] {standard_task_runner.py:107} ERROR - Failed to execute job 53 for task transformation_db (transformation_db() missing 1 required positional argument: 'df_grammys'; 212)
[2024-04-21T20:46:54.459+0000] {local_task_job_runner.py:234} INFO - Task exited with return code 1
[2024-04-21T20:46:54.526+0000] {taskinstance.py:3312} INFO - 0 downstream tasks scheduled from follow-on schedule check
